Workbook
Name Slicer_Department: #N/A
Name Slicer_Department1: #N/A
Name Slicer_Province: #N/A
Name Slicer_Province1: #N/A

Sheet Index
A2: Customer Satisfaction Analysis Dashboard
A4: Link | B4: Topic
A5: 01_Cleaned_Data | B5: The resulting table from the data cleaning process of the raw data in Power Query.
A6: 02_Lookup_Tables | B6: The tables to showcase my expertise with XLOOKUP and VLOOKUP formulas. The results are found in the columns to the right of Power Query results in the 01_Cleaned_Data Excel table.
A7: 03_Comment_List | B7: Distinct list of customer comments extracted from the survey data, with null values filtered out. Used as a lookup table to classify sentiment in Power Query.
A8: Sentiment_Map | B8: Hand-labelled lookup table assigning a sentiment (Positive, Negative or Neutral) to each unique customer comment. Merged into the main query to create the Sentiment column. Maintained manually.
A9: 04_Pivot_Tables_&_KPI_Calcs | B9: The Pivot Tables that form the foundation of the Dashboard and the resulting KPI calculations (formulas) from the initial KPI Pivot Tables.
A10: 05_Map_Data | B10: The Excel Table that feeds the Average Satisfaction by Province map chart in the Dashboard
A11: 06_Dashboard | B11: Key KPIs,customer satisfaction, revenue and performance insights
A12: 07_Extra_Analysis | B12: Detailed customer satisfaction trends and supporting insights.

Sheet 01_Cleaned_Data
A1: Index | B1: RespondentID | C1: Date | D1: Age | E1: Gender | F1: Province | G1: Product | H1: Satisfaction | I1: Recommend | J1: Payment Method | K1: Delivery Type | L1: Loyalty Member | M1: Comments | N1: Satisfaction Category | O1: Sentiment | P1: Match/Mismatch | Q1: Age Group | R1: Purchase Amount | S1: Department | T1: Region | U1: Purchase Band | V1: Month | W1: Quarter | X1: High Value Purchase | Y1: Recommendation Score | Z1: VAT Amount | AA1: Purchase Amount incl. VAT
A2: 1 | B2: R00622 | C2: 45747 | D2: 55 | E2: Other | F2: Mpumalanga | G2: Laptop Backpack | H2: 2 | I2: No | J2: Cash | K2: Click & Collect | L2: Yes | M2: Very fast delivery | N2: Dissatisfied | O2: Positive | P2: Mismatch | Q2: 55–64 | R2: =_xlfn.XLOOKUP(CleanedData[[#This Row],[Product]],'02_Lookup_Tables'!$A$2:$A$126,'02_Lookup_Tables'!$B$2:$B$126) -> 2479.57 | S2: =VLOOKUP(CleanedData[[#This Row],[Product]],'02_Lookup_Tables'!$H$2:$I$126,2,FALSE) -> Accessories | T2: =VLOOKUP(CleanedData[[#This Row],[Province]],'02_Lookup_Tables'!$D$2:$E$10,2, FALSE) -> Northern Region | U2: {=_xlfn.IFS(CleanedData[[#This Row],[Purchase Amount]]<500,"Low", CleanedData[[#This Row],[Purchase Amount]]<5000,"Medium", TRUE,"High")} -> Medium | V2: =TEXT(CleanedData[[#This Row],[Date]],"mmmm") -> March | W2: ="Q"&ROUNDUP(MONTH(CleanedData[[#This Row],[Date]])/3,0) -> Q1 | X2: =IF(CleanedData[[#This Row],[Purchase Amount]]>=5000,"Yes","No") -> No | Y2: =IF(CleanedData[[#This Row],[Recommend]]="Yes",1,0) -> 0 | Z2: =CleanedData[[#This Row],[Purchase Amount]]*0.15 -> 371.9355 | AA2: =CleanedData[[#This Row],[Purchase Amount]]*1.15 -> 2851.5055
A3: 2 | B3: R04386 | C3: 45904 | D3: 34 | E3: Male | F3: Mpumalanga | G3: Facial Cleanser | H3: 5 | I3: Yes | J3: Mobile Payment | K3: Home Delivery | L3: No | M3: Arrived damaged | N3: Very Satisfied | O3: Negative | P3: Mismatch | Q3: 25–34 | R3: =_xlfn.XLOOKUP(CleanedData[[#This Row],[Product]],'02_Lookup_Tables'!$A$2:$A$126,'02_Lookup_Tables'!$B$2:$B$126) -> 444.38 | S3: =VLOOKUP(CleanedData[[#This Row],[Product]],'02_Lookup_Tables'!$H$2:$I$126,2,FALSE) -> Beauty & Personal Care | T3: =VLOOKUP(CleanedData[[#This Row],[Province]],'02_Lookup_Tables'!$D$2:$E$10,2, FALSE) -> Northern Region | U3: {=_xlfn.IFS(CleanedData[[#This Row],[Purchase Amount]]<500,"Low", CleanedData[[#This Row],[Purchase Amount]]<5000,"Medium", TRUE,"High")} -> Low | V3: =TEXT(CleanedData[[#This Row],[Date]],"mmmm") -> September | W3: ="Q"&ROUNDUP(MONTH(CleanedData[[#This Row],[Date]])/3,0) -> Q3 | X3: =IF(CleanedData[[#This Row],[Purchase Amount]]>=5000,"Yes","No") -> No | Y3: =IF(CleanedData[[#This Row],[Recommend]]="Yes",1,0) -> 1 | Z3: =CleanedData[[#This Row],[Purchase Amount]]*0.15 -> 66.657 | AA3: =CleanedData[[#This Row],[Purchase Amount]]*1.15 -> 511.037
A4: 3 | B4: R06795 | C4: 45393 | D4: 18 | E4: Female | F4: Eastern Cape | G4: Skipping Rope | H4: 5 | I4: No | J4: Debit Card | K4: In Store | L4: No | M4: Easy to assemble | N4: Very Satisfied | O4: Positive | P4: Match | Q4: 18–24 | R4: =_xlfn.XLOOKUP(CleanedData[[#This Row],[Product]],'02_Lookup_Tables'!$A$2:$A$126,'02_Lookup_Tables'!$B$2:$B$126) -> 230.14 | S4: =VLOOKUP(CleanedData[[#This Row],[Product]],'02_Lookup_Tables'!$H$2:$I$126,2,FALSE) -> Sports & Outdoors | T4: =VLOOKUP(CleanedData[[#This Row],[Province]],'02_Lookup_Tables'!$D$2:$E$10,2, FALSE) -> Southern Region | U4: {=_xlfn.IFS(CleanedData[[#This Row],[Purchase Amount]]<500,"Low", CleanedData[[#This Row],[Purchase Amount]]<5000,"Medium", TRUE,"High")} -> Low | V4: =TEXT(CleanedData[[#This Row],[Date]],"mmmm") -> April | W4: ="Q"&ROUNDUP(MONTH(CleanedData[[#This Row],[Date]])/3,0) -> Q2 | X4: =IF(CleanedData[[#This Row],[Purchase Amount]]>=5000,"Yes","No") -> No | Y4: =IF(CleanedData[[#This Row],[Recommend]]="Yes",1,0) -> 0 | Z4: =CleanedData[[#This Row],[Purchase Amount]]*0.15 -> 34.521 | AA4: =CleanedData[[#This Row],[Purchase Amount]]*1.15 -> 264.661
A5: 4 | B5: R04563 | C5: 45646 | D5: 60 | E5: Female | F5: Limpopo | G5: Laptop Backpack | H5: 3 | I5: Yes | J5: EFT | K5: In Store | L5: Yes | M5: Easy to assemble | N5: Neutral | O5: Positive | P5: Mismatch | Q5: 55–64 | R5: =_xlfn.XLOOKUP(CleanedData[[#This Row],[Product]],'02_Lookup_Tables'!$A$2:$A$126,'02_Lookup_Tables'!$B$2:$B$126) -> 2479.57 | S5: =VLOOKUP(CleanedData[[#This Row],[Product]],'02_Lookup_Tables'!$H$2:$I$126,2,FALSE) -> Accessories | T5: =VLOOKUP(CleanedData[[#This Row],[Province]],'02_Lookup_Tables'!$D$2:$E$10,2, FALSE) -> Northern Region | U5: {=_xlfn.IFS(CleanedData[[#This Row],[Purchase Amount]]<500,"Low", CleanedData[[#This Row],[Purchase Amount]]<5000,"Medium", TRUE,"High")} -> Medium | V5: =TEXT(CleanedData[[#This Row],[Date]],"mmmm") -> December | W5: ="Q"&ROUNDUP(MONTH(CleanedData[[#This Row],[Date]])/3,0) -> Q4 | X5: =IF(CleanedData[[#This Row],[Purchase Amount]]>=5000,"Yes","No") -> No | Y5: =IF(CleanedData[[#This Row],[Recommend]]="Yes",1,0) -> 1 | Z5: =CleanedData[[#This Row],[Purchase Amount]]*0.15 -> 371.9355 | AA5: =CleanedData[[#This Row],[Purchase Amount]]*1.15 -> 2851.5055
A6: 5 | B6: R09265 | C6: 45402 | D6: 57 | E6: Male | F6: North West | G6: Breakfast Cereal | H6: 5 | I6: No | J6: Credit Card | K6: Click & Collect | L6: No | M6: Exactly as advertised | N6: Very Satisfied | O6: Positive | P6: Match | Q6: 55–64 | R6: =_xlfn.XLOOKUP(CleanedData[[#This Row],[Product]],'02_Lookup_Tables'!$A$2:$A$126,'02_Lookup_Tables'!$B$2:$B$126) -> 84.23 | S6: =VLOOKUP(CleanedData[[#This Row],[Product]],'02_Lookup_Tables'!$H$2:$I$126,2,FALSE) -> Food | T6: =VLOOKUP(CleanedData[[#This Row],[Province]],'02_Lookup_Tables'!$D$2:$E$10,2, FALSE) -> Central Region | U6: {=_xlfn.IFS(CleanedData[[#This Row],[Purchase Amount]]<500,"Low", CleanedData[[#This Row],[Purchase Amount]]<5000,"Medium", TRUE,"High")} -> Low | V6: =TEXT(CleanedData[[#This Row],[Date]],"mmmm") -> April | W6: ="Q"&ROUNDUP(MONTH(CleanedData[[#This Row],[Date]])/3,0) -> Q2 | X6: =IF(CleanedData[[#This Row],[Purchase Amount]]>=5000,"Yes","No") -> No | Y6: =IF(CleanedData[[#This Row],[Recommend]]="Yes",1,0) -> 0 | Z6: =CleanedData[[#This Row],[Purchase Amount]]*0.15 -> 12.6345 | AA6: =CleanedData[[#This Row],[Purchase Amount]]*1.15 -> 96.8645
A7: 6 | B7: R03133 | C7: 45723 | D7: 35 | E7: Male | F7: Free State | G7: Wireless Earbuds | H7: 1 | I7: No | J7: Cash | K7: Home Delivery | L7: Yes | M7: Would definitely buy again | N7: Very Dissatisfied | O7: Positive | P7: Mismatch | Q7: 35–44 | R7: =_xlfn.XLOOKUP(CleanedData[[#This Row],[Product]],'02_Lookup_Tables'!$A$2:$A$126,'02_Lookup_Tables'!$B$2:$B$126) -> 1951.09 | S7: =VLOOKUP(CleanedData[[#This Row],[Product]],'02_Lookup_Tables'!$H$2:$I$126,2,FALSE) -> Accessories | T7: =VLOOKUP(CleanedData[[#This Row],[Province]],'02_Lookup_Tables'!$D$2:$E$10,2, FALSE) -> Central Region | U7: {=_xlfn.IFS(CleanedData[[#This Row],[Purchase Amount]]<500,"Low", CleanedData[[#This Row],[Purchase Amount]]<5000,"Medium", TRUE,"High")} -> Medium | V7: =TEXT(CleanedData[[#This Row],[Date]],"mmmm") -> March | W7: ="Q"&ROUNDUP(MONTH(CleanedData[[#This Row],[Date]])/3,0) -> Q1 | X7: =IF(CleanedData[[#This Row],[Purchase Amount]]>=5000,"Yes","No") -> No | Y7: =IF(CleanedData[[#This Row],[Recommend]]="Yes",1,0) -> 0 | Z7: =CleanedData[[#This Row],[Purchase Amount]]*0.15 -> 292.6635 | AA7: =CleanedData[[#This Row],[Purchase Amount]]*1.15 -> 2243.7535
A8: 7 | B8: R08711 | C8: 45855 | D8: 22 | E8: Other | F8: Western Cape | G8: Toy Train Set | H8: 1 | I8: Yes | J8: Cash | K8: Click & Collect | L8: Yes | M8: Packaging could improve | N8: Very Dissatisfied | O8: Neutral | P8: Mismatch | Q8: 18–24 | R8: =_xlfn.XLOOKUP(CleanedData[[#This Row],[Product]],'02_Lookup_Tables'!$A$2:$A$126,'02_Lookup_Tables'!$B$2:$B$126) -> 1158.56 | S8: =VLOOKUP(CleanedData[[#This Row],[Product]],'02_Lookup_Tables'!$H$2:$I$126,2,FALSE) -> Toys & Games | T8: =VLOOKUP(CleanedData[[#This Row],[Province]],'02_Lookup_Tables'!$D$2:$E$10,2, FALSE) -> Western Region | U8: {=_xlfn.IFS(CleanedData[[#This Row],[Purchase Amount]]<500,"Low", CleanedData[[#This Row],[Purchase Amount]]<5000,"Medium", TRUE,"High")} -> Medium | V8: =TEXT(CleanedData[[#This Row],[Date]],"mmmm") -> July | W8: ="Q"&ROUNDUP(MONTH(CleanedData[[#This Row],[Date]])/3,0) -> Q3 | X8: =IF(CleanedData[[#This Row],[Purchase Amount]]>=5000,"Yes","No") -> No | Y8: =IF(CleanedData[[#This Row],[Recommend]]="Yes",1,0) -> 1 | Z8: =CleanedData[[#This Row],[Purchase Amount]]*0.15 -> 173.784 | AA8: =CleanedData[[#This Row],[Purchase Amount]]*1.15 -> 1332.344
A9: 9 | B9: R07783 | C9: 45556 | D9: 60 | E9: Male | F9: Mpumalanga | G9: Toaster | H9: 1 | I9: Yes | J9: Debit Card | K9: Click & Collect | L9: Yes | M9: Excellent product | N9: Very Dissatisfied | O9: Positive | P9: Mismatch | Q9: 55–64 | R9: =_xlfn.XLOOKUP(CleanedData[[#This Row],[Product]],'02_Lookup_Tables'!$A$2:$A$126,'02_Lookup_Tables'!$B$2:$B$126) -> 409.06 | S9: =VLOOKUP(CleanedData[[#This Row],[Product]],'02_Lookup_Tables'!$H$2:$I$126,2,FALSE) -> Home Devices | T9: =VLOOKUP(CleanedData[[#This Row],[Province]],'02_Lookup_Tables'!$D$2:$E$10,2, FALSE) -> Northern Region | U9: {=_xlfn.IFS(CleanedData[[#This Row],[Purchase Amount]]<500,"Low", CleanedData[[#This Row],[Purchase Amount]]<5000,"Medium", TRUE,"High")} -> Low | V9: =TEXT(CleanedData[[#This Row],[Date]],"mmmm") -> September | W9: ="Q"&ROUNDUP(MONTH(CleanedData[[#This Row],[Date]])/3,0) -> Q3 | X9: =IF(CleanedData[[#This Row],[Purchase Amount]]>=5000,"Yes","No") -> No | Y9: =IF(CleanedData[[#This Row],[Recommend]]="Yes",1,0) -> 1 | Z9: =CleanedData[[#This Row],[Purchase Amount]]*0.15 -> 61.359 | AA9: =CleanedData[[#This Row],[Purchase Amount]]*1.15 -> 470.419
A10: 10 | B10: R06504 | C10: 45541 | D10: 51 | E10: Male | F10: Eastern Cape | G10: Logitech Mechanical Keyboard | H10: 2 | I10: No | J10: Debit Card | K10: Home Delivery | L10: Yes | M10: Great customer service | N10: Dissatisfied | O10: Positive | P10: Mismatch | Q10: 45–54 | R10: =_xlfn.XLOOKUP(CleanedData[[#This Row],[Product]],'02_Lookup_Tables'!$A$2:$A$126,'02_Lookup_Tables'!$B$2:$B$126) -> 1370.56 | S10: =VLOOKUP(CleanedData[[#This Row],[Product]],'02_Lookup_Tables'!$H$2:$I$126,2,FALSE) -> Electronics | T10: =VLOOKUP(CleanedData[[#This Row],[Province]],'02_Lookup_Tables'!$D$2:$E$10,2, FALSE) -> Southern Region | U10: {=_xlfn.IFS(CleanedData[[#This Row],[Purchase Amount]]<500,"Low", CleanedData[[#This Row],[Purchase Amount]]<5000,"Medium", TRUE,"High")} -> Medium | V10: =TEXT(CleanedData[[#This Row],[Date]],"mmmm") -> September | W10: ="Q"&ROUNDUP(MONTH(CleanedData[[#This Row],[Date]])/3,0) -> Q3 | X10: =IF(CleanedData[[#This Row],[Purchase Amount]]>=5000,"Yes","No") -> No | Y10: =IF(CleanedData[[#This Row],[Recommend]]="Yes",1,0) -> 0 | Z10: =CleanedData[[#This Row],[Purchase Amount]]*0.15 -> 205.584 | AA10: =CleanedData[[#This Row],[Purchase Amount]]*1.15 -> 1576.144
A11: 11 | B11: R00705 | C11: 45534 | D11: 72 | E11: Female | F11: North West | G11: Apple AirPods Pro | H11: 4 | I11: No | J11: Credit Card | K11: Click & Collect | L11: Yes | M11: Packaging could improve | N11: Satisfied | O11: Neutral | P11: Mismatch | Q11: 65+ | R11: =_xlfn.XLOOKUP(CleanedData[[#This Row],[Product]],'02_Lookup_Tables'!$A$2:$A$126,'02_Lookup_Tables'!$B$2:$B$126) -> 5390.8 | S11: =VLOOKUP(CleanedData[[#This Row],[Product]],'02_Lookup_Tables'!$H$2:$I$126,2,FALSE) -> Electronics | T11: =VLOOKUP(CleanedData[[#This Row],[Province]],'02_Lookup_Tables'!$D$2:$E$10,2, FALSE) -> Central Region | U11: {=_xlfn.IFS(CleanedData[[#This Row],[Purchase Amount]]<500,"Low", CleanedData[[#This Row],[Purchase Amount]]<5000,"Medium", TRUE,"High")} -> High | V11: =TEXT(CleanedData[[#This Row],[Date]],"mmmm") -> August | W11: ="Q"&ROUNDUP(MONTH(CleanedData[[#This Row],[Date]])/3,0) -> Q3 | X11: =IF(CleanedData[[#This Row],[Purchase Amount]]>=5000,"Yes","No") -> Yes | Y11: =IF(CleanedData[[#This Row],[Recommend]]="Yes",1,0) -> 0 | Z11: =CleanedData[[#This Row],[Purchase Amount]]*0.15 -> 808.62 | AA11: =CleanedData[[#This Row],[Purchase Amount]]*1.15 -> 6199.42
A12: 12 | B12: R07667 | C12: 45749 | D12: 58 | E12: Female | F12: Eastern Cape | G12: Energy Drink | H12: 3 | I12: No | J12: Cash | K12: In Store | L12: No | M12: Instructions unclear | N12: Neutral | O12: Neutral | P12: Match | Q12: 55–64 | R12: =_xlfn.XLOOKUP(CleanedData[[#This Row],[Product]],'02_Lookup_Tables'!$A$2:$A$126,'02_Lookup_Tables'!$B$2:$B$126) -> 43.23 | S12: =VLOOKUP(CleanedData[[#This Row],[Product]],'02_Lookup_Tables'!$H$2:$I$126,2,FALSE) -> Food | T12: =VLOOKUP(CleanedData[[#This Row],[Province]],'02_Lookup_Tables'!$D$2:$E$10,2, FALSE) -> Southern Region | U12: {=_xlfn.IFS(CleanedData[[#This Row],[Purchase Amount]]<500,"Low", CleanedData[[#This Row],[Purchase Amount]]<5000,"Medium", TRUE,"High")} -> Low | V12: =TEXT(CleanedData[[#This Row],[Date]],"mmmm") -> April | W12: ="Q"&ROUNDUP(MONTH(CleanedData[[#This Row],[Date]])/3,0) -> Q2 | X12: =IF(CleanedData[[#This Row],[Purchase Amount]]>=5000,"Yes","No") -> No | Y12: =IF(CleanedData[[#This Row],[Recommend]]="Yes",1,0) -> 0 | Z12: =CleanedData[[#This Row],[Purchase Amount]]*0.15 -> 6.4845 | AA12: =CleanedData[[#This Row],[Purchase Amount]]*1.15 -> 49.7145
A13: 13 | B13: R00097 | C13: 45889 | D13: 27 | E13: Male | F13: Free State | G13: Throw Pillow | H13: 3 | I13: No | J13: Cash | K13: Click & Collect | L13: No | M13: Easy to assemble | N13: Neutral | O13: Positive | P13: Mismatch | Q13: 25–34 | R13: =_xlfn.XLOOKUP(CleanedData[[#This Row],[Product]],'02_Lookup_Tables'!$A$2:$A$126,'02_Lookup_Tables'!$B$2:$B$126) -> 276.82 | S13: =VLOOKUP(CleanedData[[#This Row],[Product]],'02_Lookup_Tables'!$H$2:$I$126,2,FALSE) -> Home & Living | T13: =VLOOKUP(CleanedData[[#This Row],[Province]],'02_Lookup_Tables'!$D$2:$E$10,2, FALSE) -> Central Region | U13: {=_xlfn.IFS(CleanedData[[#This Row],[Purchase Amount]]<500,"Low", CleanedData[[#This Row],[Purchase Amount]]<5000,"Medium", TRUE,"High")} -> Low | V13: =TEXT(CleanedData[[#This Row],[Date]],"mmmm") -> August | W13: ="Q"&ROUNDUP(MONTH(CleanedData[[#This Row],[Date]])/3,0) -> Q3 | X13: =IF(CleanedData[[#This Row],[Purchase Amount]]>=5000,"Yes","No") -> No | Y13: =IF(CleanedData[[#This Row],[Recommend]]="Yes",1,0) -> 0 | Z13: =CleanedData[[#This Row],[Purchase Amount]]*0.15 -> 41.523 | AA13: =CleanedData[[#This Row],[Purchase Amount]]*1.15 -> 318.343
... A25: 25 | B25: R09881 | C25: 45349 | D25: 62 | E25: Male | F25: Kwazulu-Natal | G25: Phone Charger | H25: 5 | I25: Yes | J25: Credit Card | K25: Home Delivery | L25: No | M25: Arrived damaged | N25: Very Satisfied | O25: Negative | P25: Mismatch | Q25: 55–64 | R25: =_xlfn.XLOOKUP(CleanedData[[#This Row],[Product]],'02_Lookup_Tables'!$A$2:$A$126,'02_Lookup_Tables'!$B$2:$B$126) -> 369.57 | S25: =VLOOKUP(CleanedData[[#This Row],[Product]],'02_Lookup_Tables'!$H$2:$I$126,2,FALSE) -> Accessories | T25: =VLOOKUP(CleanedData[[#This Row],[Province]],'02_Lookup_Tables'!$D$2:$E$10,2, FALSE) -> Eastern Region | U25: {=_xlfn.IFS(CleanedData[[#This Row],[Purchase Amount]]<500,"Low", CleanedData[[#This Row],[Purchase Amount]]<5000,"Medium", TRUE,"High")} -> Low | V25: =TEXT(CleanedData[[#This Row],[Date]],"mmmm") -> February | W25: ="Q"&ROUNDUP(MONTH(CleanedData[[#This Row],[Date]])/3,0) -> Q1 | X25: =IF(CleanedData[[#This Row],[Purchase Amount]]>=5000,"Yes","No") -> No | Y25: =IF(CleanedData[[#This Row],[Recommend]]="Yes",1,0) -> 1 | Z25: =CleanedData[[#This Row],[Purchase Amount]]*0.15 -> 55.4355 | AA25: =CleanedData[[#This Row],[Purchase Amount]]*1.15 -> 425.0055
A26: 26 | B26: R04658 | C26: 45565 | D26: 59 | E26: Female | F26: Limpopo | G26: Bed Linen Set | H26: 1 | I26: Yes | J26: Credit Card | K26: Home Delivery | L26: Yes | N26: Very Dissatisfied | O26: No Comment | P26: Not Applicable | Q26: 55–64 | R26: =_xlfn.XLOOKUP(CleanedData[[#This Row],[Product]],'02_Lookup_Tables'!$A$2:$A$126,'02_Lookup_Tables'!$B$2:$B$126) -> 1734 | S26: =VLOOKUP(CleanedData[[#This Row],[Product]],'02_Lookup_Tables'!$H$2:$I$126,2,FALSE) -> Home & Living | T26: =VLOOKUP(CleanedData[[#This Row],[Province]],'02_Lookup_Tables'!$D$2:$E$10,2, FALSE) -> Northern Region | U26: {=_xlfn.IFS(CleanedData[[#This Row],[Purchase Amount]]<500,"Low", CleanedData[[#This Row],[Purchase Amount]]<5000,"Medium", TRUE,"High")} -> Medium | V26: =TEXT(CleanedData[[#This Row],[Date]],"mmmm") -> September | W26: ="Q"&ROUNDUP(MONTH(CleanedData[[#This Row],[Date]])/3,0) -> Q3 | X26: =IF(CleanedData[[#This Row],[Purchase Amount]]>=5000,"Yes","No") -> No | Y26: =IF(CleanedData[[#This Row],[Recommend]]="Yes",1,0) -> 1 | Z26: =CleanedData[[#This Row],[Purchase Amount]]*0.15 -> 260.1 | AA26: =CleanedData[[#This Row],[Purchase Amount]]*1.15 -> 1994.1
A27: 27 | B27: R02692 | C27: 45885 | D27: 52 | E27: Female | F27: Kwazulu-Natal | G27: Bed Linen Set | H27: 3 | I27: Yes | J27: Mobile Payment | K27: In Store | L27: Yes | M27: Highly recommend | N27: Neutral | O27: Positive | P27: Mismatch | Q27: 45–54 | R27: =_xlfn.XLOOKUP(CleanedData[[#This Row],[Product]],'02_Lookup_Tables'!$A$2:$A$126,'02_Lookup_Tables'!$B$2:$B$126) -> 1734 | S27: =VLOOKUP(CleanedData[[#This Row],[Product]],'02_Lookup_Tables'!$H$2:$I$126,2,FALSE) -> Home & Living | T27: =VLOOKUP(CleanedData[[#This Row],[Province]],'02_Lookup_Tables'!$D$2:$E$10,2, FALSE) -> Eastern Region | U27: {=_xlfn.IFS(CleanedData[[#This Row],[Purchase Amount]]<500,"Low", CleanedData[[#This Row],[Purchase Amount]]<5000,"Medium", TRUE,"High")} -> Medium | V27: =TEXT(CleanedData[[#This Row],[Date]],"mmmm") -> August | W27: ="Q"&ROUNDUP(MONTH(CleanedData[[#This Row],[Date]])/3,0) -> Q3 | X27: =IF(CleanedData[[#This Row],[Purchase Amount]]>=5000,"Yes","No") -> No | Y27: =IF(CleanedData[[#This Row],[Recommend]]="Yes",1,0) -> 1 | Z27: =CleanedData[[#This Row],[Purchase Amount]]*0.15 -> 260.1 | AA27: =CleanedData[[#This Row],[Purchase Amount]]*1.15 -> 1994.1
A28: 28 | B28: R04890 | C28: 45606 | D28: 35 | E28: Male | F28: Eastern Cape | G28: Breakfast Cereal | H28: 4 | I28: No | J28: Mobile Payment | K28: Click & Collect | L28: Yes | M28: Average quality | N28: Satisfied | O28: Neutral | P28: Mismatch | Q28: 35–44 | R28: =_xlfn.XLOOKUP(CleanedData[[#This Row],[Product]],'02_Lookup_Tables'!$A$2:$A$126,'02_Lookup_Tables'!$B$2:$B$126) -> 84.23 | S28: =VLOOKUP(CleanedData[[#This Row],[Product]],'02_Lookup_Tables'!$H$2:$I$126,2,FALSE) -> Food | T28: =VLOOKUP(CleanedData[[#This Row],[Province]],'02_Lookup_Tables'!$D$2:$E$10,2, FALSE) -> Southern Region | U28: {=_xlfn.IFS(CleanedData[[#This Row],[Purchase Amount]]<500,"Low", CleanedData[[#This Row],[Purchase Amount]]<5000,"Medium", TRUE,"High")} -> Low | V28: =TEXT(CleanedData[[#This Row],[Date]],"mmmm") -> November | W28: ="Q"&ROUNDUP(MONTH(CleanedData[[#This Row],[Date]])/3,0) -> Q4 | X28: =IF(CleanedData[[#This Row],[Purchase Amount]]>=5000,"Yes","No") -> No | Y28: =IF(CleanedData[[#This Row],[Recommend]]="Yes",1,0) -> 0 | Z28: =CleanedData[[#This Row],[Purchase Amount]]*0.15 -> 12.6345 | AA28: =CleanedData[[#This Row],[Purchase Amount]]*1.15 -> 96.8645
A29: 29 | B29: R09279 | C29: 45361 | D29: 44 | E29: Male | F29: Limpopo | G29: Running Shoes | H29: 1 | I29: Yes | J29: Debit Card | K29: Click & Collect | L29: Yes | M29: Product was disappointing | N29: Very Dissatisfied | O29: Negative | P29: Match | Q29: 35–44 | R29: =_xlfn.XLOOKUP(CleanedData[[#This Row],[Product]],'02_Lookup_Tables'!$A$2:$A$126,'02_Lookup_Tables'!$B$2:$B$126) -> 2340.57 | S29: =VLOOKUP(CleanedData[[#This Row],[Product]],'02_Lookup_Tables'!$H$2:$I$126,2,FALSE) -> Apparel | T29: =VLOOKUP(CleanedData[[#This Row],[Province]],'02_Lookup_Tables'!$D$2:$E$10,2, FALSE) -> Northern Region | U29: {=_xlfn.IFS(CleanedData[[#This Row],[Purchase Amount]]<500,"Low", CleanedData[[#This Row],[Purchase Amount]]<5000,"Medium", TRUE,"High")} -> Medium | V29: =TEXT(CleanedData[[#This Row],[Date]],"mmmm") -> March | W29: ="Q"&ROUNDUP(MONTH(CleanedData[[#This Row],[Date]])/3,0) -> Q1 | X29: =IF(CleanedData[[#This Row],[Purchase Amount]]>=5000,"Yes","No") -> No | Y29: =IF(CleanedData[[#This Row],[Recommend]]="Yes",1,0) -> 1 | Z29: =CleanedData[[#This Row],[Purchase Amount]]*0.15 -> 351.0855 | AA29: =CleanedData[[#This Row],[Purchase Amount]]*1.15 -> 2691.6555
A30: 30 | B30: R09198 | C30: 45445 | D30: 46 | E30: Other | F30: Western Cape | G30: Nikon Mirrorless Camera | H30: 4 | I30: No | J30: EFT | K30: Home Delivery | L30: No | M30: Great customer service | N30: Satisfied | O30: Positive | P30: Match | Q30: 45–54 | R30: =_xlfn.XLOOKUP(CleanedData[[#This Row],[Product]],'02_Lookup_Tables'!$A$2:$A$126,'02_Lookup_Tables'!$B$2:$B$126) -> 44114.21 | S30: =VLOOKUP(CleanedData[[#This Row],[Product]],'02_Lookup_Tables'!$H$2:$I$126,2,FALSE) -> Electronics | T30: =VLOOKUP(CleanedData[[#This Row],[Province]],'02_Lookup_Tables'!$D$2:$E$10,2, FALSE) -> Western Region | U30: {=_xlfn.IFS(CleanedData[[#This Row],[Purchase Amount]]<500,"Low", CleanedData[[#This Row],[Purchase Amount]]<5000,"Medium", TRUE,"High")} -> High | V30: =TEXT(CleanedData[[#This Row],[Date]],"mmmm") -> June | W30: ="Q"&ROUNDUP(MONTH(CleanedData[[#This Row],[Date]])/3,0) -> Q2 | X30: =IF(CleanedData[[#This Row],[Purchase Amount]]>=5000,"Yes","No") -> Yes | Y30: =IF(CleanedData[[#This Row],[Recommend]]="Yes",1,0) -> 0 | Z30: =CleanedData[[#This Row],[Purchase Amount]]*0.15 -> 6617.1315 | AA30: =CleanedData[[#This Row],[Purchase Amount]]*1.15 -> 50731.341
A31: 32 | B31: R04218 | C31: 45376 | D31: 59 | E31: Male | F31: Eastern Cape | G31: Hiking Backpack | H31: 2 | I31: Yes | J31: Cash | K31: Click & Collect | L31: No | M31: Item missing accessories | N31: Dissatisfied | O31: Negative | P31: Match | Q31: 55–64 | R31: =_xlfn.XLOOKUP(CleanedData[[#This Row],[Product]],'02_Lookup_Tables'!$A$2:$A$126,'02_Lookup_Tables'!$B$2:$B$126) -> 4455.18 | S31: =VLOOKUP(CleanedData[[#This Row],[Product]],'02_Lookup_Tables'!$H$2:$I$126,2,FALSE) -> Sports & Outdoors | T31: =VLOOKUP(CleanedData[[#This Row],[Province]],'02_Lookup_Tables'!$D$2:$E$10,2, FALSE) -> Southern Region | U31: {=_xlfn.IFS(CleanedData[[#This Row],[Purchase Amount]]<500,"Low", CleanedData[[#This Row],[Purchase Amount]]<5000,"Medium", TRUE,"High")} -> Medium | V31: =TEXT(CleanedData[[#This Row],[Date]],"mmmm") -> March | W31: ="Q"&ROUNDUP(MONTH(CleanedData[[#This Row],[Date]])/3,0) -> Q1 | X31: =IF(CleanedData[[#This Row],[Purchase Amount]]>=5000,"Yes","No") -> No | Y31: =IF(CleanedData[[#This Row],[Recommend]]="Yes",1,0) -> 1 | Z31: =CleanedData[[#This Row],[Purchase Amount]]*0.15 -> 668.277 | AA31: =CleanedData[[#This Row],[Purchase Amount]]*1.15 -> 5123.457
A32: 33 | B32: R09153 | C32: 45727 | D32: 34 | E32: Female | F32: Eastern Cape | G32: Apple iPad | H32: 4 | I32: No | J32: Credit Card | K32: In Store | L32: Yes | M32: Poor packaging | N32: Satisfied | O32: Negative | P32: Mismatch | Q32: 25–34 | R32: =_xlfn.XLOOKUP(CleanedData[[#This Row],[Product]],'02_Lookup_Tables'!$A$2:$A$126,'02_Lookup_Tables'!$B$2:$B$126) -> 27815.44 | S32: =VLOOKUP(CleanedData[[#This Row],[Product]],'02_Lookup_Tables'!$H$2:$I$126,2,FALSE) -> Electronics | T32: =VLOOKUP(CleanedData[[#This Row],[Province]],'02_Lookup_Tables'!$D$2:$E$10,2, FALSE) -> Southern Region | U32: {=_xlfn.IFS(CleanedData[[#This Row],[Purchase Amount]]<500,"Low", CleanedData[[#This Row],[Purchase Amount]]<5000,"Medium", TRUE,"High")} -> High | V32: =TEXT(CleanedData[[#This Row],[Date]],"mmmm") -> March | W32: ="Q"&ROUNDUP(MONTH(CleanedData[[#This Row],[Date]])/3,0) -> Q1 | X32: =IF(CleanedData[[#This Row],[Purchase Amount]]>=5000,"Yes","No") -> Yes | Y32: =IF(CleanedData[[#This Row],[Recommend]]="Yes",1,0) -> 0 | Z32: =CleanedData[[#This Row],[Purchase Amount]]*0.15 -> 4172.316 | AA32: =CleanedData[[#This Row],[Purchase Amount]]*1.15 -> 31987.756
A33: 34 | B33: R04844 | C33: 45796 | D33: 31 | E33: Male | F33: Eastern Cape | G33: Samsung 55-inch Smart TV | H33: 5 | I33: No | J33: Cash | K33: Click & Collect | L33: Yes | M33: Helpful staff | N33: Very Satisfied | O33: Positive | P33: Match | Q33: 25–34 | R33: =_xlfn.XLOOKUP(CleanedData[[#This Row],[Product]],'02_Lookup_Tables'!$A$2:$A$126,'02_Lookup_Tables'!$B$2:$B$126) -> 14808.31 | S33: =VLOOKUP(CleanedData[[#This Row],[Product]],'02_Lookup_Tables'!$H$2:$I$126,2,FALSE) -> Electronics | T33: =VLOOKUP(CleanedData[[#This Row],[Province]],'02_Lookup_Tables'!$D$2:$E$10,2, FALSE) -> Southern Region | U33: {=_xlfn.IFS(CleanedData[[#This Row],[Purchase Amount]]<500,"Low", CleanedData[[#This Row],[Purchase Amount]]<5000,"Medium", TRUE,"High")} -> High | V33: =TEXT(CleanedData[[#This Row],[Date]],"mmmm") -> May | W33: ="Q"&ROUNDUP(MONTH(CleanedData[[#This Row],[Date]])/3,0) -> Q2 | X33: =IF(CleanedData[[#This Row],[Purchase Amount]]>=5000,"Yes","No") -> Yes | Y33: =IF(CleanedData[[#This Row],[Recommend]]="Yes",1,0) -> 0 | Z33: =CleanedData[[#This Row],[Purchase Amount]]*0.15 -> 2221.2465 | AA33: =CleanedData[[#This Row],[Purchase Amount]]*1.15 -> 17029.556
A34: 35 | B34: R06787 | C34: 45915 | D34: 22 | E34: Male | F34: Northern Cape | G34: Leather Wallet | H34: 4 | I34: No | J34: Cash | K34: Home Delivery | L34: No | M34: Great customer service | N34: Satisfied | O34: Positive | P34: Match | Q34: 18–24 | R34: =_xlfn.XLOOKUP(CleanedData[[#This Row],[Product]],'02_Lookup_Tables'!$A$2:$A$126,'02_Lookup_Tables'!$B$2:$B$126) -> 1011.68 | S34: =VLOOKUP(CleanedData[[#This Row],[Product]],'02_Lookup_Tables'!$H$2:$I$126,2,FALSE) -> Accessories | T34: =VLOOKUP(CleanedData[[#This Row],[Province]],'02_Lookup_Tables'!$D$2:$E$10,2, FALSE) -> Western Region | U34: {=_xlfn.IFS(CleanedData[[#This Row],[Purchase Amount]]<500,"Low", CleanedData[[#This Row],[Purchase Amount]]<5000,"Medium", TRUE,"High")} -> Medium | V34: =TEXT(CleanedData[[#This Row],[Date]],"mmmm") -> September | W34: ="Q"&ROUNDUP(MONTH(CleanedData[[#This Row],[Date]])/3,0) -> Q3 | X34: =IF(CleanedData[[#This Row],[Purchase Amount]]>=5000,"Yes","No") -> No | Y34: =IF(CleanedData[[#This Row],[Recommend]]="Yes",1,0) -> 0 | Z34: =CleanedData[[#This Row],[Purchase Amount]]*0.15 -> 151.752 | AA34: =CleanedData[[#This Row],[Purchase Amount]]*1.15 -> 1163.432
A35: 36 | B35: R03111 | C35: 45920 | D35: 34 | E35: Other | F35: Eastern Cape | G35: Camping Chair | H35: 3 | I35: Yes | J35: Cash | K35: Home Delivery | L35: Yes | M35: Delivery delayed | N35: Neutral | O35: Negative | P35: Mismatch | Q35: 25–34 | R35: =_xlfn.XLOOKUP(CleanedData[[#This Row],[Product]],'02_Lookup_Tables'!$A$2:$A$126,'02_Lookup_Tables'!$B$2:$B$126) -> 1355.08 | S35: =VLOOKUP(CleanedData[[#This Row],[Product]],'02_Lookup_Tables'!$H$2:$I$126,2,FALSE) -> Sports & Outdoors | T35: =VLOOKUP(CleanedData[[#This Row],[Province]],'02_Lookup_Tables'!$D$2:$E$10,2, FALSE) -> Southern Region | U35: {=_xlfn.IFS(CleanedData[[#This Row],[Purchase Amount]]<500,"Low", CleanedData[[#This Row],[Purchase Amount]]<5000,"Medium", TRUE,"High")} -> Medium | V35: =TEXT(CleanedData[[#This Row],[Date]],"mmmm") -> September | W35: ="Q"&ROUNDUP(MONTH(CleanedData[[#This Row],[Date]])/3,0) -> Q3 | X35: =IF(CleanedData[[#This Row],[Purchase Amount]]>=5000,"Yes","No") -> No | Y35: =IF(CleanedData[[#This Row],[Recommend]]="Yes",1,0) -> 1 | Z35: =CleanedData[[#This Row],[Purchase Amount]]*0.15 -> 203.262 | AA35: =CleanedData[[#This Row],[Purchase Amount]]*1.15 -> 1558.342
A36: 37 | B36: R00440 | C36: 45785 | D36: 60 | E36: Male | F36: Northern Cape | G36: Tennis Racket | H36: 1 | I36: No | J36: Debit Card | K36: Home Delivery | L36: No | N36: Very Dissatisfied | O36: No Comment | P36: Not Applicable | Q36: 55–64 | R36: =_xlfn.XLOOKUP(CleanedData[[#This Row],[Product]],'02_Lookup_Tables'!$A$2:$A$126,'02_Lookup_Tables'!$B$2:$B$126) -> 2962.6 | S36: =VLOOKUP(CleanedData[[#This Row],[Product]],'02_Lookup_Tables'!$H$2:$I$126,2,FALSE) -> Sports & Outdoors | T36: =VLOOKUP(CleanedData[[#This Row],[Province]],'02_Lookup_Tables'!$D$2:$E$10,2, FALSE) -> Western Region | U36: {=_xlfn.IFS(CleanedData[[#This Row],[Purchase Amount]]<500,"Low", CleanedData[[#This Row],[Purchase Amount]]<5000,"Medium", TRUE,"High")} -> Medium | V36: =TEXT(CleanedData[[#This Row],[Date]],"mmmm") -> May | W36: ="Q"&ROUNDUP(MONTH(CleanedData[[#This Row],[Date]])/3,0) -> Q2 | X36: =IF(CleanedData[[#This Row],[Purchase Amount]]>=5000,"Yes","No") -> No | Y36: =IF(CleanedData[[#This Row],[Recommend]]="Yes",1,0) -> 0 | Z36: =CleanedData[[#This Row],[Purchase Amount]]*0.15 -> 444.39 | AA36: =CleanedData[[#This Row],[Purchase Amount]]*1.15 -> 3406.99
A37: 38 | B37: R02474 | C37: 45513 | D37: 20 | E37: Male | F37: Limpopo | G37: Puzzle 1000 Pieces | H37: 5 | I37: Yes | J37: Cash | K37: Click & Collect | L37: Yes | N37: Very Satisfied | O37: No Comment | P37: Not Applicable | Q37: 18–24 | R37: =_xlfn.XLOOKUP(CleanedData[[#This Row],[Product]],'02_Lookup_Tables'!$A$2:$A$126,'02_Lookup_Tables'!$B$2:$B$126) -> 294.33 | S37: =VLOOKUP(CleanedData[[#This Row],[Product]],'02_Lookup_Tables'!$H$2:$I$126,2,FALSE) -> Toys & Games | T37: =VLOOKUP(CleanedData[[#This Row],[Province]],'02_Lookup_Tables'!$D$2:$E$10,2, FALSE) -> Northern Region | U37: {=_xlfn.IFS(CleanedData[[#This Row],[Purchase Amount]]<500,"Low", CleanedData[[#This Row],[Purchase Amount]]<5000,"Medium", TRUE,"High")} -> Low | V37: =TEXT(CleanedData[[#This Row],[Date]],"mmmm") -> August | W37: ="Q"&ROUNDUP(MONTH(CleanedData[[#This Row],[Date]])/3,0) -> Q3 | X37: =IF(CleanedData[[#This Row],[Purchase Amount]]>=5000,"Yes","No") -> No | Y37: =IF(CleanedData[[#This Row],[Recommend]]="Yes",1,0) -> 1 | Z37: =CleanedData[[#This Row],[Purchase Amount]]*0.15 -> 44.1495 | AA37: =CleanedData[[#This Row],[Purchase Amount]]*1.15 -> 338.4795
A38: 39 | B38: R06096 | C38: 45319 | D38: 77 | E38: Female | F38: North West | G38: Curtains | H38: 3 | I38: Yes | J38: EFT | K38: In Store | L38: Yes | M38: Product exceeded expectations | N38: Neutral | O38: Positive | P38: Mismatch | Q38: 65+ | R38: =_xlfn.XLOOKUP(CleanedData[[#This Row],[Product]],'02_Lookup_Tables'!$A$2:$A$126,'02_Lookup_Tables'!$B$2:$B$126) -> 3086.4 | S38: =VLOOKUP(CleanedData[[#This Row],[Product]],'02_Lookup_Tables'!$H$2:$I$126,2,FALSE) -> Home & Living | T38: =VLOOKUP(CleanedData[[#This Row],[Province]],'02_Lookup_Tables'!$D$2:$E$10,2, FALSE) -> Central Region | U38: {=_xlfn.IFS(CleanedData[[#This Row],[Purchase Amount]]<500,"Low", CleanedData[[#This Row],[Purchase Amount]]<5000,"Medium", TRUE,"High")} -> Medium | V38: =TEXT(CleanedData[[#This Row],[Date]],"mmmm") -> January | W38: ="Q"&ROUNDUP(MONTH(CleanedData[[#This Row],[Date]])/3,0) -> Q1 | X38: =IF(CleanedData[[#This Row],[Purchase Amount]]>=5000,"Yes","No") -> No | Y38: =IF(CleanedData[[#This Row],[Recommend]]="Yes",1,0) -> 1 | Z38: =CleanedData[[#This Row],[Purchase Amount]]*0.15 -> 462.96 | AA38: =CleanedData[[#This Row],[Purchase Amount]]*1.15 -> 3549.36
A39: 40 | B39: R09146 | C39: 45666 | E39: Female | F39: North West | G39: Storage Basket | H39: 3 | I39: Yes | J39: Debit Card | K39: Click & Collect | L39: No | M39: Excellent value | N39: Neutral | O39: Positive | P39: Mismatch | Q39: Unknown | R39: =_xlfn.XLOOKUP(CleanedData[[#This Row],[Product]],'02_Lookup_Tables'!$A$2:$A$126,'02_Lookup_Tables'!$B$2:$B$126) -> 440.87 | S39: =VLOOKUP(CleanedData[[#This Row],[Product]],'02_Lookup_Tables'!$H$2:$I$126,2,FALSE) -> Home & Living | T39: =VLOOKUP(CleanedData[[#This Row],[Province]],'02_Lookup_Tables'!$D$2:$E$10,2, FALSE) -> Central Region | U39: {=_xlfn.IFS(CleanedData[[#This Row],[Purchase Amount]]<500,"Low", CleanedData[[#This Row],[Purchase Amount]]<5000,"Medium", TRUE,"High")} -> Low | V39: =TEXT(CleanedData[[#This Row],[Date]],"mmmm") -> January | W39: ="Q"&ROUNDUP(MONTH(CleanedData[[#This Row],[Date]])/3,0) -> Q1 | X39: =IF(CleanedData[[#This Row],[Purchase Amount]]>=5000,"Yes","No") -> No | Y39: =IF(CleanedData[[#This Row],[Recommend]]="Yes",1,0) -> 1 | Z39: =CleanedData[[#This Row],[Purchase Amount]]*0.15 -> 66.1305 | AA39: =CleanedData[[#This Row],[Purchase Amount]]*1.15 -> 507.0005
A40: 41 | B40: R07774 | C40: 45700 | D40: 29 | E40: Male | F40: Western Cape | G40: Samsung Galaxy Tablet | H40: 5 | I40: Yes | J40: Mobile Payment | K40: In Store | L40: No | M40: Excellent product | N40: Very Satisfied | O40: Positive | P40: Match | Q40: 25–34 | R40: =_xlfn.XLOOKUP(CleanedData[[#This Row],[Product]],'02_Lookup_Tables'!$A$2:$A$126,'02_Lookup_Tables'!$B$2:$B$126) -> 14729.04 | S40: =VLOOKUP(CleanedData[[#This Row],[Product]],'02_Lookup_Tables'!$H$2:$I$126,2,FALSE) -> Electronics | T40: =VLOOKUP(CleanedData[[#This Row],[Province]],'02_Lookup_Tables'!$D$2:$E$10,2, FALSE) -> Western Region | U40: {=_xlfn.IFS(CleanedData[[#This Row],[Purchase Amount]]<500,"Low", CleanedData[[#This Row],[Purchase Amount]]<5000,"Medium", TRUE,"High")} -> High | V40: =TEXT(CleanedData[[#This Row],[Date]],"mmmm") -> February | W40: ="Q"&ROUNDUP(MONTH(CleanedData[[#This Row],[Date]])/3,0) -> Q1 | X40: =IF(CleanedData[[#This Row],[Purchase Amount]]>=5000,"Yes","No") -> Yes | Y40: =IF(CleanedData[[#This Row],[Recommend]]="Yes",1,0) -> 1 | Z40: =CleanedData[[#This Row],[Purchase Amount]]*0.15 -> 2209.356 | AA40: =CleanedData[[#This Row],[Purchase Amount]]*1.15 -> 16938.396
A41: 42 | B41: R01569 | C41: 45547 | D41: 65 | E41: Male | F41: Western Cape | G41: Facial Cleanser | H41: 4 | I41: Yes | J41: Debit Card | K41: Home Delivery | L41: Yes | M41: Instructions unclear | N41: Satisfied | O41: Neutral | P41: Mismatch | Q41: 65+ | R41: =_xlfn.XLOOKUP(CleanedData[[#This Row],[Product]],'02_Lookup_Tables'!$A$2:$A$126,'02_Lookup_Tables'!$B$2:$B$126) -> 444.38 | S41: =VLOOKUP(CleanedData[[#This Row],[Product]],'02_Lookup_Tables'!$H$2:$I$126,2,FALSE) -> Beauty & Personal Care | T41: =VLOOKUP(CleanedData[[#This Row],[Province]],'02_Lookup_Tables'!$D$2:$E$10,2, FALSE) -> Western Region | U41: {=_xlfn.IFS(CleanedData[[#This Row],[Purchase Amount]]<500,"Low", CleanedData[[#This Row],[Purchase Amount]]<5000,"Medium", TRUE,"High")} -> Low | V41: =TEXT(CleanedData[[#This Row],[Date]],"mmmm") -> September | W41: ="Q"&ROUNDUP(MONTH(CleanedData[[#This Row],[Date]])/3,0) -> Q3 | X41: =IF(CleanedData[[#This Row],[Purchase Amount]]>=5000,"Yes","No") -> No | Y41: =IF(CleanedData[[#This Row],[Recommend]]="Yes",1,0) -> 1 | Z41: =CleanedData[[#This Row],[Purchase Amount]]*0.15 -> 66.657 | AA41: =CleanedData[[#This Row],[Purchase Amount]]*1.15 -> 511.037
A42: 43 | B42: R02733 | C42: 45768 | D42: 44 | E42: Other | F42: Free State | G42: Vacuum Cleaner | H42: 1 | I42: No | J42: Cash | K42: Click & Collect | L42: No | M42: Delivery delayed | N42: Very Dissatisfied | O42: Negative | P42: Match | Q42: 35–44 | R42: =_xlfn.XLOOKUP(CleanedData[[#This Row],[Product]],'02_Lookup_Tables'!$A$2:$A$126,'02_Lookup_Tables'!$B$2:$B$126) -> 6710.27 | S42: =VLOOKUP(CleanedData[[#This Row],[Product]],'02_Lookup_Tables'!$H$2:$I$126,2,FALSE) -> Home Devices | T42: =VLOOKUP(CleanedData[[#This Row],[Province]],'02_Lookup_Tables'!$D$2:$E$10,2, FALSE) -> Central Region | U42: {=_xlfn.IFS(CleanedData[[#This Row],[Purchase Amount]]<500,"Low", CleanedData[[#This Row],[Purchase Amount]]<5000,"Medium", TRUE,"High")} -> High | V42: =TEXT(CleanedData[[#This Row],[Date]],"mmmm") -> April | W42: ="Q"&ROUNDUP(MONTH(CleanedData[[#This Row],[Date]])/3,0) -> Q2 | X42: =IF(CleanedData[[#This Row],[Purchase Amount]]>=5000,"Yes","No") -> Yes | Y42: =IF(CleanedData[[#This Row],[Recommend]]="Yes",1,0) -> 0 | Z42: =CleanedData[[#This Row],[Purchase Amount]]*0.15 -> 1006.5405 | AA42: =CleanedData[[#This Row],[Purchase Amount]]*1.15 -> 7716.8105
A43: 44 | B43: R00170 | C43: 45367 | D43: 46 | E43: Male | F43: Free State | G43: Bose Soundbar | H43: 3 | I43: No | J43: Mobile Payment | K43: In Store | L43: No | M43: Excellent value | N43: Neutral | O43: Positive | P43: Mismatch | Q43: 45–54 | R43: =_xlfn.XLOOKUP(CleanedData[[#This Row],[Product]],'02_Lookup_Tables'!$A$2:$A$126,'02_Lookup_Tables'!$B$2:$B$126) -> 13056.99 | S43: =VLOOKUP(CleanedData[[#This Row],[Product]],'02_Lookup_Tables'!$H$2:$I$126,2,FALSE) -> Electronics | T43: =VLOOKUP(CleanedData[[#This Row],[Province]],'02_Lookup_Tables'!$D$2:$E$10,2, FALSE) -> Central Region | U43: {=_xlfn.IFS(CleanedData[[#This Row],[Purchase Amount]]<500,"Low", CleanedData[[#This Row],[Purchase Amount]]<5000,"Medium", TRUE,"High")} -> High | V43: =TEXT(CleanedData[[#This Row],[Date]],"mmmm") -> March | W43: ="Q"&ROUNDUP(MONTH(CleanedData[[#This Row],[Date]])/3,0) -> Q1 | X43: =IF(CleanedData[[#This Row],[Purchase Amount]]>=5000,"Yes","No") -> Yes | Y43: =IF(CleanedData[[#This Row],[Recommend]]="Yes",1,0) -> 0 | Z43: =CleanedData[[#This Row],[Purchase Amount]]*0.15 -> 1958.5485 | AA43: =CleanedData[[#This Row],[Purchase Amount]]*1.15 -> 15015.538
A44: 45 | B44: R09284 | C44: 45482 | D44: 59 | E44: Male | F44: Western Cape | G44: Laptop Backpack | H44: 2 | I44: Yes | J44: Cash | K44: Home Delivery | L44: No | M44: Easy online ordering | N44: Dissatisfied | O44: Positive | P44: Mismatch | Q44: 55–64 | R44: =_xlfn.XLOOKUP(CleanedData[[#This Row],[Product]],'02_Lookup_Tables'!$A$2:$A$126,'02_Lookup_Tables'!$B$2:$B$126) -> 2479.57 | S44: =VLOOKUP(CleanedData[[#This Row],[Product]],'02_Lookup_Tables'!$H$2:$I$126,2,FALSE) -> Accessories | T44: =VLOOKUP(CleanedData[[#This Row],[Province]],'02_Lookup_Tables'!$D$2:$E$10,2, FALSE) -> Western Region | U44: {=_xlfn.IFS(CleanedData[[#This Row],[Purchase Amount]]<500,"Low", CleanedData[[#This Row],[Purchase Amount]]<5000,"Medium", TRUE,"High")} -> Medium | V44: =TEXT(CleanedData[[#This Row],[Date]],"mmmm") -> July | W44: ="Q"&ROUNDUP(MONTH(CleanedData[[#This Row],[Date]])/3,0) -> Q3 | X44: =IF(CleanedData[[#This Row],[Purchase Amount]]>=5000,"Yes","No") -> No | Y44: =IF(CleanedData[[#This Row],[Recommend]]="Yes",1,0) -> 1 | Z44: =CleanedData[[#This Row],[Purchase Amount]]*0.15 -> 371.9355 | AA44: =CleanedData[[#This Row],[Purchase Amount]]*1.15 -> 2851.5055
A45: 47 | B45: R07916 | C45: 45848 | D45: 71 | E45: Other | F45: Free State | G45: Winter Jacket | H45: 1 | I45: No | J45: Debit Card | K45: Home Delivery | L45: No | M45: Product was disappointing | N45: Very Dissatisfied | O45: Negative | P45: Match | Q45: 65+ | R45: =_xlfn.XLOOKUP(CleanedData[[#This Row],[Product]],'02_Lookup_Tables'!$A$2:$A$126,'02_Lookup_Tables'!$B$2:$B$126) -> 3747.26 | S45: =VLOOKUP(CleanedData[[#This Row],[Product]],'02_Lookup_Tables'!$H$2:$I$126,2,FALSE) -> Apparel | T45: =VLOOKUP(CleanedData[[#This Row],[Province]],'02_Lookup_Tables'!$D$2:$E$10,2, FALSE) -> Central Region | U45: {=_xlfn.IFS(CleanedData[[#This Row],[Purchase Amount]]<500,"Low", CleanedData[[#This Row],[Purchase Amount]]<5000,"Medium", TRUE,"High")} -> Medium | V45: =TEXT(CleanedData[[#This Row],[Date]],"mmmm") -> July | W45: ="Q"&ROUNDUP(MONTH(CleanedData[[#This Row],[Date]])/3,0) -> Q3 | X45: =IF(CleanedData[[#This Row],[Purchase Amount]]>=5000,"Yes","No") -> No | Y45: =IF(CleanedData[[#This Row],[Recommend]]="Yes",1,0) -> 0 | Z45: =CleanedData[[#This Row],[Purchase Amount]]*0.15 -> 562.089 | AA45: =CleanedData[[#This Row],[Purchase Amount]]*1.15 -> 4309.349
A46: 48 | B46: R05685 | C46: 45507 | D46: 74 | E46: Other | F46: Mpumalanga | G46: Apple AirPods Pro | H46: 4 | I46: Yes | J46: Debit Card | K46: In Store | L46: No | M46: Helpful staff | N46: Satisfied | O46: Positive | P46: Match | Q46: 65+ | R46: =_xlfn.XLOOKUP(CleanedData[[#This Row],[Product]],'02_Lookup_Tables'!$A$2:$A$126,'02_Lookup_Tables'!$B$2:$B$126) -> 5390.8 | S46: =VLOOKUP(CleanedData[[#This Row],[Product]],'02_Lookup_Tables'!$H$2:$I$126,2,FALSE) -> Electronics | T46: =VLOOKUP(CleanedData[[#This Row],[Province]],'02_Lookup_Tables'!$D$2:$E$10,2, FALSE) -> Northern Region | U46: {=_xlfn.IFS(CleanedData[[#This Row],[Purchase Amount]]<500,"Low", CleanedData[[#This Row],[Purchase Amount]]<5000,"Medium", TRUE,"High")} -> High | V46: =TEXT(CleanedData[[#This Row],[Date]],"mmmm") -> August | W46: ="Q"&ROUNDUP(MONTH(CleanedData[[#This Row],[Date]])/3,0) -> Q3 | X46: =IF(CleanedData[[#This Row],[Purchase Amount]]>=5000,"Yes","No") -> Yes | Y46: =IF(CleanedData[[#This Row],[Recommend]]="Yes",1,0) -> 1 | Z46: =CleanedData[[#This Row],[Purchase Amount]]*0.15 -> 808.62 | AA46: =CleanedData[[#This Row],[Purchase Amount]]*1.15 -> 6199.42
A47: 49 | B47: R09981 | C47: 45784 | D47: 37 | E47: Male | F47: Northern Cape | G47: Fruit Juice | H47: 5 | I47: No | J47: Credit Card | K47: Home Delivery | L47: No | M47: Fits perfectly | N47: Very Satisfied | O47: Positive | P47: Match | Q47: 35–44 | R47: =_xlfn.XLOOKUP(CleanedData[[#This Row],[Product]],'02_Lookup_Tables'!$A$2:$A$126,'02_Lookup_Tables'!$B$2:$B$126) -> 54.82 | S47: =VLOOKUP(CleanedData[[#This Row],[Product]],'02_Lookup_Tables'!$H$2:$I$126,2,FALSE) -> Food | T47: =VLOOKUP(CleanedData[[#This Row],[Province]],'02_Lookup_Tables'!$D$2:$E$10,2, FALSE) -> Western Region | U47: {=_xlfn.IFS(CleanedData[[#This Row],[Purchase Amount]]<500,"Low", CleanedData[[#This Row],[Purchase Amount]]<5000,"Medium", TRUE,"High")} -> Low | V47: =TEXT(CleanedData[[#This Row],[Date]],"mmmm") -> May | W47: ="Q"&ROUNDUP(MONTH(CleanedData[[#This Row],[Date]])/3,0) -> Q2 | X47: =IF(CleanedData[[#This Row],[Purchase Amount]]>=5000,"Yes","No") -> No | Y47: =IF(CleanedData[[#This Row],[Recommend]]="Yes",1,0) -> 0 | Z47: =CleanedData[[#This Row],[Purchase Amount]]*0.15 -> 8.223 | AA47: =CleanedData[[#This Row],[Purchase Amount]]*1.15 -> 63.043
A48: 51 | B48: R05082 | C48: 45743 | D48: 42 | E48: Other | F48: Western Cape | G48: Ceiling Fan | H48: 2 | I48: Yes | J48: Mobile Payment | K48: Click & Collect | L48: No | M48: Product was disappointing | N48: Dissatisfied | O48: Negative | P48: Match | Q48: 35–44 | R48: =_xlfn.XLOOKUP(CleanedData[[#This Row],[Product]],'02_Lookup_Tables'!$A$2:$A$126,'02_Lookup_Tables'!$B$2:$B$126) -> 3715.65 | S48: =VLOOKUP(CleanedData[[#This Row],[Product]],'02_Lookup_Tables'!$H$2:$I$126,2,FALSE) -> Home Devices | T48: =VLOOKUP(CleanedData[[#This Row],[Province]],'02_Lookup_Tables'!$D$2:$E$10,2, FALSE) -> Western Region | U48: {=_xlfn.IFS(CleanedData[[#This Row],[Purchase Amount]]<500,"Low", CleanedData[[#This Row],[Purchase Amount]]<5000,"Medium", TRUE,"High")} -> Medium | V48: =TEXT(CleanedData[[#This Row],[Date]],"mmmm") -> March | W48: ="Q"&ROUNDUP(MONTH(CleanedData[[#This Row],[Date]])/3,0) -> Q1 | X48: =IF(CleanedData[[#This Row],[Purchase Amount]]>=5000,"Yes","No") -> No | Y48: =IF(CleanedData[[#This Row],[Recommend]]="Yes",1,0) -> 1 | Z48: =CleanedData[[#This Row],[Purchase Amount]]*0.15 -> 557.3475 | AA48: =CleanedData[[#This Row],[Purchase Amount]]*1.15 -> 4272.9975
A49: 52 | B49: R02288 | C49: 45620 | D49: 66 | E49: Other | F49: Free State | G49: Camping Chair | H49: 4 | I49: No | J49: EFT | K49: In Store | L49: Yes | M49: Long waiting time | N49: Satisfied | O49: Negative | P49: Mismatch | Q49: 65+ | R49: =_xlfn.XLOOKUP(CleanedData[[#This Row],[Product]],'02_Lookup_Tables'!$A$2:$A$126,'02_Lookup_Tables'!$B$2:$B$126) -> 1355.08 | S49: =VLOOKUP(CleanedData[[#This Row],[Product]],'02_Lookup_Tables'!$H$2:$I$126,2,FALSE) -> Sports & Outdoors | T49: =VLOOKUP(CleanedData[[#This Row],[Province]],'02_Lookup_Tables'!$D$2:$E$10,2, FALSE) -> Central Region | U49: {=_xlfn.IFS(CleanedData[[#This Row],[Purchase Amount]]<500,"Low", CleanedData[[#This Row],[Purchase Amount]]<5000,"Medium", TRUE,"High")} -> Medium | V49: =TEXT(CleanedData[[#This Row],[Date]],"mmmm") -> November | W49: ="Q"&ROUNDUP(MONTH(CleanedData[[#This Row],[Date]])/3,0) -> Q4 | X49: =IF(CleanedData[[#This Row],[Purchase Amount]]>=5000,"Yes","No") -> No | Y49: =IF(CleanedData[[#This Row],[Recommend]]="Yes",1,0) -> 0 | Z49: =CleanedData[[#This Row],[Purchase Amount]]*0.15 -> 203.262 | AA49: =CleanedData[[#This Row],[Purchase Amount]]*1.15 -> 1558.342
A50: 55 | B50: R01982 | C50: 45789 | D50: 33 | E50: Other | F50: Gauteng | G50: Watch Strap | H50: 5 | I50: Yes | J50: Cash | K50: Home Delivery | L50: Yes | M50: Great customer service | N50: Very Satisfied | O50: Positive | P50: Match | Q50: 25–34 | R50: =_xlfn.XLOOKUP(CleanedData[[#This Row],[Product]],'02_Lookup_Tables'!$A$2:$A$126,'02_Lookup_Tables'!$B$2:$B$126) -> 368.99 | S50: =VLOOKUP(CleanedData[[#This Row],[Product]],'02_Lookup_Tables'!$H$2:$I$126,2,FALSE) -> Accessories | T50: =VLOOKUP(CleanedData[[#This Row],[Province]],'02_Lookup_Tables'!$D$2:$E$10,2, FALSE) -> Gauteng Region | U50: {=_xlfn.IFS(CleanedData[[#This Row],[Purchase Amount]]<500,"Low", CleanedData[[#This Row],[Purchase Amount]]<5000,"Medium", TRUE,"High")} -> Low | V50: =TEXT(CleanedData[[#This Row],[Date]],"mmmm") -> May | W50: ="Q"&ROUNDUP(MONTH(CleanedData[[#This Row],[Date]])/3,0) -> Q2 | X50: =IF(CleanedData[[#This Row],[Purchase Amount]]>=5000,"Yes","No") -> No | Y50: =IF(CleanedData[[#This Row],[Recommend]]="Yes",1,0) -> 1 | Z50: =CleanedData[[#This Row],[Purchase Amount]]*0.15 -> 55.3485 | AA50: =CleanedData[[#This Row],[Purchase Amount]]*1.15 -> 424.3385
A51: 58 | B51: R04848 | C51: 45507 | D51: 28 | E51: Other | F51: Limpopo | G51: Dell Inspiron Laptop | H51: 3 | I51: No | J51: Debit Card | K51: Home Delivery | L51: Yes | M51: Instructions unclear | N51: Neutral | O51: Neutral | P51: Match | Q51: 25–34 | R51: =_xlfn.XLOOKUP(CleanedData[[#This Row],[Product]],'02_Lookup_Tables'!$A$2:$A$126,'02_Lookup_Tables'!$B$2:$B$126) -> 24904.86 | S51: =VLOOKUP(CleanedData[[#This Row],[Product]],'02_Lookup_Tables'!$H$2:$I$126,2,FALSE) -> Electronics | T51: =VLOOKUP(CleanedData[[#This Row],[Province]],'02_Lookup_Tables'!$D$2:$E$10,2, FALSE) -> Northern Region | U51: {=_xlfn.IFS(CleanedData[[#This Row],[Purchase Amount]]<500,"Low", CleanedData[[#This Row],[Purchase Amount]]<5000,"Medium", TRUE,"High")} -> High | V51: =TEXT(CleanedData[[#This Row],[Date]],"mmmm") -> August | W51: ="Q"&ROUNDUP(MONTH(CleanedData[[#This Row],[Date]])/3,0) -> Q3 | X51: =IF(CleanedData[[#This Row],[Purchase Amount]]>=5000,"Yes","No") -> Yes | Y51: =IF(CleanedData[[#This Row],[Recommend]]="Yes",1,0) -> 0 | Z51: =CleanedData[[#This Row],[Purchase Amount]]*0.15 -> 3735.729 | AA51: =CleanedData[[#This Row],[Purchase Amount]]*1.15 -> 28640.589
...

Sheet 02_Lookup_Tables
A1: Product | B1: Purchase Amount | D1: Province | E1: Region | H1: Product | I1: Department
A2: Sony PlayStation 5 | B2: 11052.57 | D2: Eastern Cape | E2: Southern Region | H2: Samsung 55-inch Smart TV | I2: Electronics
A3: Peanut Butter | B3: 103.4 | D3: Free State | E3: Central Region | H3: Apple AirPods Pro | I3: Electronics
A4: Polo Shirt | B4: 786.78 | D4: Gauteng | E4: Gauteng Region | H4: HP Pavilion Laptop | I4: Electronics
A5: Board Game | B5: 1000.7 | D5: KwaZulu-Natal | E5: Eastern Region | H5: Lenovo ThinkPad Laptop | I5: Electronics
A6: Wall Clock | B6: 768.34 | D6: Limpopo | E6: Northern Region | H6: Dell Inspiron Laptop | I6: Electronics
A7: Breakfast Cereal | B7: 84.23 | D7: Mpumalanga | E7: Northern Region | H7: Sony PlayStation 5 | I7: Electronics
A8: Kitchen Knife Set | B8: 2849.09 | D8: Northern Cape | E8: Western Region | H8: Xbox Series X | I8: Electronics
A9: Chocolate Gift Box | B9: 353.21 | D9: North West | E9: Central Region | H9: Nintendo Switch OLED | I9: Electronics
A10: Sunglasses | B10: 1907.49 | D10: Western Cape | E10: Western Region | H10: Canon EOS DSLR Camera | I10: Electronics
A11: Remote Control Drone | B11: 8798.49 | H11: Nikon Mirrorless Camera | I11: Electronics
A12: Washing Machine | B12: 10347.71 | H12: JBL Bluetooth Speaker | I12: Electronics
A13: Organic Coffee Beans | B13: 343.42 | H13: Bose Soundbar | I13: Electronics
A14: Canon EOS DSLR Camera | B14: 13261 | H14: Logitech Wireless Mouse | I14: Electronics
A15: Cookware Set | B15: 2906.97 | H15: Logitech Mechanical Keyboard | I15: Electronics
A16: Toaster | B16: 409.06 | H16: Apple iPad | I16: Electronics
A17: Barbie Doll | B17: 306.57 | H17: Samsung Galaxy Tablet | I17: Electronics
A18: Nintendo Switch OLED | B18: 6581.78 | H18: Garmin Smartwatch | I18: Electronics
A19: Tennis Racket | B19: 2962.6 | H19: Fitbit Fitness Tracker | I19: Electronics
A20: USB-C Cable | B20: 283.57 | H20: Organic Coffee Beans | I20: Food
A21: Ceramic Dinner Set | B21: 2572.02 | H21: Breakfast Cereal | I21: Food
A22: Electric Kettle | B22: 657.5 | H22: Olive Oil | I22: Food
... A125: Bed Linen Set | B125: 1734 | H125: Toy Train Set | I125: Toys & Games
H126: Samsung Smart TV | I126: Electronics

Sheet 03_Comment_List
A1: Comments
A2: Worth the money
A3: Delivery delayed
A4: Great customer service
A5: Would definitely buy again
A6: Highly recommend
A7: Easy to assemble
A8: Product exceeded expectations
A9: Very comfortable
A10: Item missing accessories
A11: Arrived damaged
A12: Long waiting time
... A27: Poor packaging

Sheet Sentiment_Map
A1: Comments | B1: Sentiment
A2: Worth the money | B2: Positive
A3: Delivery delayed | B3: Negative
A4: Great customer service | B4: Positive
A5: Would definitely buy again | B5: Positive
A6: Highly recommend | B6: Positive
A7: Easy to assemble | B7: Positive
A8: Product exceeded expectations | B8: Positive
A9: Very comfortable | B9: Positive
A10: Item missing accessories | B10: Negative
A11: Arrived damaged | B11: Negative
A12: Long waiting time | B12: Negative
... A27: Poor packaging | B27: Negative

Sheet 04_Pivot_Tables_&_KPI_Calcs
A1: Total Respondents | C1: Average of Satisfaction | E1: Total Revenue | G1: Recommendation | H1: Tota Respondents | J1: Average of Purchase Amount | L1: Match/Mismatch | M1: Total Respondents
A2: 8347 | C2: 3.0015574 | E2: 28214082 | G2: No | H2: 4161 | J2: 3380.1464 | L2: Match | M2: 2927
G3: Yes | H3: 4186 | L3: Mismatch | M3: 4783
A4: KPI Calculations: | G4: Grand Total | H4: 8347 | L4: Not Applicable | M4: 637
A5: Total Respondents | C5: Average Satisfaction | E5: Overall Revenue | H5: Positive Sentiment % | J5: Average Purchase | L5: Grand Total | M5: 8347
A6: =GETPIVOTDATA("RespondentID",$A$1) -> 8347 | C6: =TEXT(GETPIVOTDATA("Satisfaction",'04_Pivot_Tables_&_KPI_Calcs'!$C$1),"0.0")&" / 5" -> 3.0 / 5 | E6: =GETPIVOTDATA("Purchase Amount",$E$1) -> 28214082 | H6: =GETPIVOTDATA("RespondentID",$G$1,"Recommend","Yes")/GETPIVOTDATA("RespondentID",$G$1) -> 0.50149754 | J6: =GETPIVOTDATA("Purchase Amount",$J$1) -> 3380.1464 | L6: Rating–Comment Agreement %
M7: =GETPIVOTDATA("Total Respondents",$L$1,"Match/Mismatch","Match") / (GETPIVOTDATA("Total Respondents",$L$1,"Match/Mismatch","Match") + GETPIVOTDATA("Total Respondents",$L$1,"Match/Mismatch","Mismatch")) -> 0.37963684
O8: Top 10 Products by Revenue | R8: Top 10 Products by Revenue (Respondent Count) | V8: Bottom 10 Products by Revenue | Y8: Bottom 10 Products by Revenue (Respondent Count)
O9: Products | P9: Total Revenue | R9: Products | S9: Total Revenue | T9: Total Respondents | V9: Products | W9: Total Revenue | Y9: Products | Z9: Total Revenue | AA9: Total Respondents
O10: Nikon Mirrorless Camera | P10: 2955652.1 | R10: Nikon Mirrorless Camera | S10: 2955652.1 | T10: 67 | V10: Instant Noodles | W10: 1641 | Y10: Instant Noodles | Z10: 1641 | AA10: 60
O11: Apple iPad | P11: 2141788.9 | R11: Apple iPad | S11: 2141788.9 | T11: 77 | V11: Bottled Water | W11: 1949.4 | Y11: Bottled Water | Z11: 1949.4 | AA11: 57
A12: Top 10 Products by Average Satisfaction | D12: Top 10 Products by Average Satisfaction (Respondent Count) | H12: Bottom 10 Products by Average Satisfaction | K12: Bottom 10 Products by Average Satisfaction (Respondent Count) | O12: Dell Inspiron Laptop | P12: 1693530.5 | R12: Dell Inspiron Laptop | S12: 1693530.5 | T12: 68 | V12: Protein Bars | W12: 2527.8 | Y12: Protein Bars | Z12: 2527.8 | AA12: 55
A13: Products | B13: Average of Satisfaction | D13: Products | E13: Average of Satisfaction | F13: Total Respondents | H13: Products | I13: Average of Satisfaction | K13: Products | L13: Average of Satisfaction | M13: Total Respondents | O13: Lenovo ThinkPad Laptop | P13: 1602821.4 | R13: Lenovo ThinkPad Laptop | S13: 1602821.4 | T13: 71 | V13: Pasta | W13: 3284.85 | Y13: Pasta | Z13: 3284.85 | AA13: 61
A14: Portable Heater | B14: 3.2608696 | D14: Portable Heater | E14: 3.2608696 | F14: 69 | H14: Shampoo | I14: 2.744186 | K14: Shampoo | L14: 2.744186 | M14: 86 | O14: Samsung Galaxy Tablet | P14: 1207781.3 | R14: Samsung Galaxy Tablet | S14: 1207781.3 | T14: 82 | V14: Fruit Juice | W14: 3289.2 | Y14: Fruit Juice | Z14: 3289.2 | AA14: 60
A15: Plush Teddy Bear | B15: 3.2674419 | D15: Plush Teddy Bear | E15: 3.2674419 | F15: 86 | H15: Trail Mix | I15: 2.7368421 | K15: Trail Mix | L15: 2.7368421 | M15: 57 | O15: HP Pavilion Laptop | P15: 1040980.5 | R15: HP Pavilion Laptop | S15: 1040980.5 | T15: 63 | V15: Energy Drink | W15: 3458.4 | Y15: Energy Drink | Z15: 3458.4 | AA15: 80
A16: Protein Bars | B16: 3.2727273 | D16: Protein Bars | E16: 3.2727273 | F16: 55 | H16: Logitech Wireless Mouse | I16: 2.7323944 | K16: Logitech Wireless Mouse | L16: 2.7323944 | M16: 71 | O16: Canon EOS DSLR Camera | P16: 1034358 | R16: Canon EOS DSLR Camera | S16: 1034358 | T16: 78 | V16: Potato Chips | W16: 3650.01 | Y16: Potato Chips | Z16: 3650.01 | AA16: 91
A17: Fitness Tracker | B17: 3.2816901 | D17: Fitness Tracker | E17: 3.2816901 | F17: 71 | H17: Power Bank | I17: 2.7297297 | K17: Power Bank | L17: 2.7297297 | M17: 74 | O17: Bose Soundbar | P17: 979274.25 | R17: Bose Soundbar | S17: 979274.25 | T17: 75 | V17: Lip Balm | W17: 4177.25 | Y17: Lip Balm | Z17: 4177.25 | AA17: 49
A18: Canon EOS DSLR Camera | B18: 3.2820513 | D18: Canon EOS DSLR Camera | E18: 3.2820513 | F18: 78 | H18: Watch Strap | I18: 2.7073171 | K18: Watch Strap | L18: 2.7073171 | M18: 82 | O18: Robot Vacuum | P18: 928616.64 | R18: Robot Vacuum | S18: 928616.64 | T18: 57 | V18: Green Tea | W18: 5155.68 | Y18: Green Tea | Z18: 5155.68 | AA18: 69
A19: Fitbit Fitness Tracker | B19: 3.3428571 | D19: Fitbit Fitness Tracker | E19: 3.3428571 | F19: 70 | H19: Air Fryer | I19: 2.6769231 | K19: Air Fryer | L19: 2.6769231 | M19: 65 | O19: Samsung 55-inch Smart TV | P19: 844073.67 | R19: Samsung 55-inch Smart TV | S19: 844073.67 | T19: 57 | V19: Breakfast Cereal | W19: 5390.72 | Y19: Breakfast Cereal | Z19: 5390.72 | AA19: 64
A20: Beard Trimmer | B20: 3.3478261 | D20: Beard Trimmer | E20: 3.3478261 | F20: 69 | H20: Electric Kettle | I20: 2.6760563 | K20: Electric Kettle | L20: 2.6760563 | M20: 71
A21: Phone Charger | B21: 3.3809524 | D21: Phone Charger | E21: 3.3809524 | F21: 63 | H21: Lenovo ThinkPad Laptop | I21: 2.6619718 | K21: Lenovo ThinkPad Laptop | L21: 2.6619718 | M21: 71
A22: Bicycle Helmet | B22: 3.4383562 | D22: Bicycle Helmet | E22: 3.4383562 | F22: 73 | H22: Samsung 55-inch Smart TV | I22: 2.6491228 | K22: Samsung 55-inch Smart TV | L22: 2.6491228 | M22: 57
A23: Hair Straightener | B23: 3.5342466 | D23: Hair Straightener | E23: 3.5342466 | F23: 73 | H23: Body Lotion | I23: 2.6153846 | K23: Body Lotion | L23: 2.6153846 | M23: 52
O25: Average Satisfaction by Age Group (Respondent Count) | S25: Average Purchase by Gender | V25: Average Purchase by Gender( Respondent Count)
O26: Age Groups | P26: Average of Satisfaction | Q26: Total Respondents | S26: Gender | T26: Average of Purchase Amount | V26: Gender | W26: Average of Purchase Amount | X26: Total Respondents
O27: 18–24 | P27: 3.0022173 | Q27: 902 | S27: Female | T27: 3295.7157 | V27: Female | W27: 3295.7157 | X27: 2765
O28: 25–34 | P28: 2.9469937 | Q28: 1264 | S28: Male | T28: 3285.1225 | V28: Male | W28: 3285.1225 | X28: 2806
O29: 35–44 | P29: 3.055205 | Q29: 1268 | S29: Other | T29: 3560.2932 | V29: Other | W29: 3560.2932 | X29: 2776
O30: 45–54 | P30: 2.9527931 | Q30: 1271
A31: Revenue by Department | D31: Revenue by Department (Respondent Count) | O31: 55–64 | P31: 3.0364964 | Q31: 1233
A32: Department | B32: Total Revenue | D32: Department | E32: Total Revenue | F32: Total Respondents | O32: 65+ | P32: 3.0125847 | Q32: 2066
A33: Electronics | B33: 16683022 | D33: Electronics | E33: 16683022 | F33: 1267 | O33: Unknown | P33: 2.9912536 | Q33: 343
A34: Home Devices | B34: 3679280.5 | D34: Home Devices | E34: 3679280.5 | F34: 930
A35: Sports & Outdoors | B35: 2163765 | D35: Sports & Outdoors | E35: 2163765 | F35: 790
A36: Home & Living | B36: 1685931.9 | D36: Home & Living | E36: 1685931.9 | F36: 849
A37: Toys & Games | B37: 1223106.2 | D37: Toys & Games | E37: 1223106.2 | F37: 811
A38: Accessories | B38: 1002475.1 | D38: Accessories | E38: 1002475.1 | F38: 879 | H38: Average Satisfaction for each Province | L38: Average Satisfaction by Age Group
A39: Apparel | B39: 918610.94 | D39: Apparel | E39: 918610.94 | F39: 858 | H39: Provinces | I39: Average of Satisfaction | J39: Total Respondents | L39: Age Groups | M39: Average of Satisfaction
A40: Beauty & Personal Care | B40: 718573.23 | D40: Beauty & Personal Care | E40: 718573.23 | F40: 891 | H40: Eastern Cape | I40: 3.0042872 | J40: 933 | L40: 18–24 | M40: 3.0022173
A41: Food | B41: 139316.51 | D41: Food | E41: 139316.51 | F41: 1072 | H41: Free State | I41: 3.0107181 | J41: 933 | L41: 25–34 | M41: 2.9469937
...

Sheet 05_Map_Data
A1: Province | B1: Average Satisfaction
A2: Eastern Cape | B2: =GETPIVOTDATA("Satisfaction",'04_Pivot_Tables_&_KPI_Calcs'!$H$39,"Province",A2) -> 3.0042872
A3: Free State | B3: =GETPIVOTDATA("Satisfaction",'04_Pivot_Tables_&_KPI_Calcs'!$H$39,"Province",A3) -> 3.0107181
A4: Gauteng | B4: =GETPIVOTDATA("Satisfaction",'04_Pivot_Tables_&_KPI_Calcs'!$H$39,"Province",A4) -> 2.9787709
A5: Kwazulu-Natal | B5: =GETPIVOTDATA("Satisfaction",'04_Pivot_Tables_&_KPI_Calcs'!$H$39,"Province",A5) -> 2.9354486
A6: Limpopo | B6: =GETPIVOTDATA("Satisfaction",'04_Pivot_Tables_&_KPI_Calcs'!$H$39,"Province",A6) -> 3.0247469
A7: Mpumalanga | B7: =GETPIVOTDATA("Satisfaction",'04_Pivot_Tables_&_KPI_Calcs'!$H$39,"Province",A7) -> 3.0344478
A8: North West | B8: =GETPIVOTDATA("Satisfaction",'04_Pivot_Tables_&_KPI_Calcs'!$H$39,"Province",A8) -> 2.980063
A9: Northern Cape | B9: =GETPIVOTDATA("Satisfaction",'04_Pivot_Tables_&_KPI_Calcs'!$H$39,"Province",A9) -> 3.0389884
A10: Western Cape | B10: =GETPIVOTDATA("Satisfaction",'04_Pivot_Tables_&_KPI_Calcs'!$H$39,"Province",A10) -> 3.0033557

Sheet 06_Dashboard
A2: Customer Satisfaction Dashboard
C7: ='04_Pivot_Tables_&_KPI_Calcs'!A6 -> 8347 | F7: ='04_Pivot_Tables_&_KPI_Calcs'!C6 -> 3.0 / 5 | H7: ='04_Pivot_Tables_&_KPI_Calcs'!J6 -> 3380.1464 | K7: ='04_Pivot_Tables_&_KPI_Calcs'!H6 -> 0.50149754

Sheet 07_Extra_Analysis
F1: Additional Analysis
B6: ='04_Pivot_Tables_&_KPI_Calcs'!E6 -> 28214082 | F6: ='04_Pivot_Tables_&_KPI_Calcs'!M7 -> 0.37963684
